# Uso detallado de try...catch en JavaScript

El bloque `try...catch` en JavaScript se usa para manejar errores de manera controlada y evitar que estos detengan la ejecución del programa. Permite detectar y responder a excepciones (errores inesperados) de manera eficiente.

## Sintaxis básica

```javascript
try {
  // Código que podría generar un error
} catch (error) {
  // Código que maneja el error
}
```

## Explicación

- **`try`**: Contiene el código que se ejecutará y que podría generar un error.
- **`catch`**: Se ejecuta si ocurre un error en el bloque `try`, recibiendo el objeto de error como argumento.

## Ejemplo simple

```javascript
try {
  let resultado = 10 / 0; // No genera error en JS, pero ilustra la idea
  console.log(resultado);
} catch (error) {
  console.log('Ocurrió un error:', error.message);
}
```

## Uso de `throw new Error(...)`

Se puede lanzar un error personalizado con `throw new Error(...)` para manejar casos específicos.

### Ejemplo con `throw new Error(...)`

```javascript
function dividir(a, b) {
  if (b === 0) {
    throw new Error('No se puede dividir por cero');
  }
  return a / b;
}

try {
  let resultado = dividir(10, 0);
  console.log('Resultado:', resultado);
} catch (error) {
  console.log('Error detectado:', error.message);
}
```

## Agregando `finally`

El bloque `finally` se ejecuta siempre, ocurra o no un error.

```javascript
try {
  console.log('Intentando ejecutar código...');
  throw new Error('Algo salió mal');
} catch (error) {
  console.log('Error capturado:', error.message);
} finally {
  console.log('Este bloque se ejecuta siempre');
}
```

### Beneficios de `try...catch`

- Evita que errores inesperados detengan la ejecución del código.
- Permite definir respuestas personalizadas a errores.
- Facilita la depuración y manejo de errores en aplicaciones web.

¡Espero que esto te ayude a entender `try...catch` en JavaScript! 🚀